<?xml version="1.0" encoding="UTF-8"?>
<testng-results retried="1" ignored="1" total="3" passed="0" failed="1" skipped="0">
  <reporter-output>
  </reporter-output>
  <suite started-at="2023-03-19T10:16:04 WAT" name="Suite" finished-at="2023-03-19T10:16:50 WAT" duration-ms="45223">
    <groups>
      <group name="errorHandling">
        <method signature="ErrorValidationTest.errorLogin()[pri:0, instance:ErrorValidationTest@27216cd]" name="errorLogin" class="ErrorValidationTest"/>
      </group> <!-- errorHandling -->
    </groups>
    <test started-at="2023-03-19T10:16:04 WAT" name="order" finished-at="2023-03-19T10:16:05 WAT" duration-ms="104">
    </test> <!-- order -->
    <test started-at="2023-03-19T10:16:04 WAT" name="error validation" finished-at="2023-03-19T10:16:50 WAT" duration-ms="45223">
      <class name="ErrorValidationTest">
        <test-method is-config="true" signature="launchBrowser()[pri:0, instance:ErrorValidationTest@27216cd]" started-at="2023-03-19T10:16:05 WAT" name="launchBrowser" finished-at="2023-03-19T10:16:38 WAT" duration-ms="33212" status="PASS">
          <reporter-output>
          </reporter-output>
        </test-method> <!-- launchBrowser -->
        <test-method retried="true" signature="errorLogin()[pri:0, instance:ErrorValidationTest@27216cd]" started-at="2023-03-19T10:16:38 WAT" name="errorLogin" finished-at="2023-03-19T10:16:39 WAT" duration-ms="852" status="SKIP">
          <exception class="java.lang.AssertionError">
            <message>
              <![CDATA[expected [Incorrect email or password] but found [Incorrect email or password.]]]>
            </message>
            <full-stacktrace>
              <![CDATA[java.lang.AssertionError: expected [Incorrect email or password] but found [Incorrect email or password.]
at org.testng.Assert.fail(Assert.java:110)
at org.testng.Assert.failNotEquals(Assert.java:1577)
at org.testng.Assert.assertEqualsImpl(Assert.java:149)
at org.testng.Assert.assertEquals(Assert.java:131)
at org.testng.Assert.assertEquals(Assert.java:655)
at org.testng.Assert.assertEquals(Assert.java:665)
at ErrorValidationTest.errorLogin(ErrorValidationTest.java:12)
at java.base/jdk.internal.reflect.NativeMethodAccessorImpl.invoke0(Native Method)
at java.base/jdk.internal.reflect.NativeMethodAccessorImpl.invoke(NativeMethodAccessorImpl.java:62)
at java.base/jdk.internal.reflect.DelegatingMethodAccessorImpl.invoke(DelegatingMethodAccessorImpl.java:43)
at java.base/java.lang.reflect.Method.invoke(Method.java:566)
at org.testng.internal.invokers.MethodInvocationHelper.invokeMethod(MethodInvocationHelper.java:139)
at org.testng.internal.invokers.TestInvoker.invokeMethod(TestInvoker.java:677)
at org.testng.internal.invokers.TestInvoker.invokeTestMethod(TestInvoker.java:221)
at org.testng.internal.invokers.MethodRunner.runInSequence(MethodRunner.java:50)
at org.testng.internal.invokers.TestInvoker$MethodInvocationAgent.invoke(TestInvoker.java:969)
at org.testng.internal.invokers.TestInvoker.invokeTestMethods(TestInvoker.java:194)
at org.testng.internal.invokers.TestMethodWorker.invokeTestMethods(TestMethodWorker.java:148)
at org.testng.internal.invokers.TestMethodWorker.run(TestMethodWorker.java:128)
at java.base/java.util.ArrayList.forEach(ArrayList.java:1541)
at org.testng.TestRunner.privateRun(TestRunner.java:829)
at org.testng.TestRunner.run(TestRunner.java:602)
at org.testng.SuiteRunner.runTest(SuiteRunner.java:437)
at org.testng.SuiteRunner$SuiteWorker.run(SuiteRunner.java:475)
at org.testng.internal.thread.ThreadUtil.lambda$execute$0(ThreadUtil.java:58)
at java.base/java.util.concurrent.FutureTask.run(FutureTask.java:264)
at java.base/java.util.concurrent.ThreadPoolExecutor.runWorker(ThreadPoolExecutor.java:1128)
at java.base/java.util.concurrent.ThreadPoolExecutor$Worker.run(ThreadPoolExecutor.java:628)
at java.base/java.lang.Thread.run(Thread.java:834)
]]>
            </full-stacktrace>
          </exception> <!-- java.lang.AssertionError -->
          <reporter-output>
          </reporter-output>
        </test-method> <!-- errorLogin -->
        <test-method is-config="true" signature="terminate()[pri:0, instance:ErrorValidationTest@27216cd]" started-at="2023-03-19T10:16:39 WAT" name="terminate" finished-at="2023-03-19T10:16:39 WAT" duration-ms="627" status="PASS">
          <reporter-output>
          </reporter-output>
        </test-method> <!-- terminate -->
        <test-method is-config="true" signature="launchBrowser()[pri:0, instance:ErrorValidationTest@27216cd]" started-at="2023-03-19T10:16:39 WAT" name="launchBrowser" finished-at="2023-03-19T10:16:48 WAT" duration-ms="8138" status="PASS">
          <reporter-output>
          </reporter-output>
        </test-method> <!-- launchBrowser -->
        <test-method signature="errorLogin()[pri:0, instance:ErrorValidationTest@27216cd]" started-at="2023-03-19T10:16:48 WAT" name="errorLogin" finished-at="2023-03-19T10:16:49 WAT" duration-ms="1117" status="FAIL">
          <exception class="java.lang.AssertionError">
            <message>
              <![CDATA[expected [Incorrect email or password] but found [Incorrect email or password.]]]>
            </message>
            <full-stacktrace>
              <![CDATA[java.lang.AssertionError: expected [Incorrect email or password] but found [Incorrect email or password.]
at org.testng.Assert.fail(Assert.java:110)
at org.testng.Assert.failNotEquals(Assert.java:1577)
at org.testng.Assert.assertEqualsImpl(Assert.java:149)
at org.testng.Assert.assertEquals(Assert.java:131)
at org.testng.Assert.assertEquals(Assert.java:655)
at org.testng.Assert.assertEquals(Assert.java:665)
at ErrorValidationTest.errorLogin(ErrorValidationTest.java:12)
at java.base/jdk.internal.reflect.NativeMethodAccessorImpl.invoke0(Native Method)
at java.base/jdk.internal.reflect.NativeMethodAccessorImpl.invoke(NativeMethodAccessorImpl.java:62)
at java.base/jdk.internal.reflect.DelegatingMethodAccessorImpl.invoke(DelegatingMethodAccessorImpl.java:43)
at java.base/java.lang.reflect.Method.invoke(Method.java:566)
at org.testng.internal.invokers.MethodInvocationHelper.invokeMethod(MethodInvocationHelper.java:139)
at org.testng.internal.invokers.TestInvoker.invokeMethod(TestInvoker.java:677)
at org.testng.internal.invokers.TestInvoker.retryFailed(TestInvoker.java:263)
at org.testng.internal.invokers.MethodRunner.runInSequence(MethodRunner.java:62)
at org.testng.internal.invokers.TestInvoker$MethodInvocationAgent.invoke(TestInvoker.java:969)
at org.testng.internal.invokers.TestInvoker.invokeTestMethods(TestInvoker.java:194)
at org.testng.internal.invokers.TestMethodWorker.invokeTestMethods(TestMethodWorker.java:148)
at org.testng.internal.invokers.TestMethodWorker.run(TestMethodWorker.java:128)
at java.base/java.util.ArrayList.forEach(ArrayList.java:1541)
at org.testng.TestRunner.privateRun(TestRunner.java:829)
at org.testng.TestRunner.run(TestRunner.java:602)
at org.testng.SuiteRunner.runTest(SuiteRunner.java:437)
at org.testng.SuiteRunner$SuiteWorker.run(SuiteRunner.java:475)
at org.testng.internal.thread.ThreadUtil.lambda$execute$0(ThreadUtil.java:58)
at java.base/java.util.concurrent.FutureTask.run(FutureTask.java:264)
at java.base/java.util.concurrent.ThreadPoolExecutor.runWorker(ThreadPoolExecutor.java:1128)
at java.base/java.util.concurrent.ThreadPoolExecutor$Worker.run(ThreadPoolExecutor.java:628)
at java.base/java.lang.Thread.run(Thread.java:834)
]]>
            </full-stacktrace>
          </exception> <!-- java.lang.AssertionError -->
          <reporter-output>
          </reporter-output>
        </test-method> <!-- errorLogin -->
        <test-method is-config="true" signature="terminate()[pri:0, instance:ErrorValidationTest@27216cd]" started-at="2023-03-19T10:16:49 WAT" name="terminate" finished-at="2023-03-19T10:16:50 WAT" duration-ms="482" status="PASS">
          <reporter-output>
          </reporter-output>
        </test-method> <!-- terminate -->
      </class> <!-- ErrorValidationTest -->
    </test> <!-- error validation -->
  </suite> <!-- Suite -->
</testng-results>
